Workbook

Sheet Call List
A1: Call list — Portaria 140/2026, ranked by eligible claim
A2: Eligible GWh is COMPUTED from ONS half-hourly constrained-off data for 1 Sep 2023 – 25 Nov 2025, REL + CNF only. It is not a company disclosure. Ownership is a join through ANEEL SIGA — check the confidence column.
A4: # | B4: Group / holder | C4: Conf. | D4: States | E4: Complexes | F4: Eligible GWh | G4: % of pool | H4: Est. gross claim (R$m) | I4: Indexed to payment (R$m) | J4: Sobreoferta GWh (waived, never paid) | K4: Operating MW | L4: Why they take the call | M4: What to ask on call one
A5: 1 | B5: Casa dos Ventos | C5: M | D5: BA,PE,PI,RN | E5: 23 | F5: 4753.5 | G5: =F5/Assumptions!$B$7 | H5: =F5*1000*Assumptions!$B$8/1000000 | I5: =H5*(1+Assumptions!$B$9) | J5: 3519.2 | K5: 8419 | L5: Largest single holder of eligible claim in the country — and privately held, so no analyst has done this work for them. Rio do Vento and Serra do Mel clusters. Ask what share of the cut volume sat outside CCEAR-D/CER. | M5: 1) What share of your cut volume was committed to CCEAR-D or CER? 2) What do you owe CCEE in delivery-shortfall ressarcimentos? 3) What is your sobreoferta volume over the window, and what have you assumed it is worth? 4) Are you in any of the twelve suits, or in the ABEEólica/ABSOLAR collective action?
A6: 2 | B6: Engie Brasil Energia | C6: H | D6: BA,CE,RN | E6: 10 | F6: 1775.5 | G6: =F6/Assumptions!$B$7 | H6: =F6*1000*Assumptions!$B$8/1000000 | I6: =H6*(1+Assumptions!$B$9) | J6: 1433.9 | K6: 3054 | L6: Named its own worst assets in its 4T25 release (Santo Agostinho 36%, Trairi 31%). Discloses curtailment only in percentages — has never put an R$ figure on it publicly. Fitch estimates R$150m of 2025 EBITDA impact. | M6: 1) What share of your cut volume was committed to CCEAR-D or CER? 2) What do you owe CCEE in delivery-shortfall ressarcimentos? 3) What is your sobreoferta volume over the window, and what have you assumed it is worth? 4) Are you in any of the twelve suits, or in the ABEEólica/ABSOLAR collective action?
A7: 3 | B7: Enel Green Power Brasil | C7: H | D7: BA,PI,RN | E7: 13 | F7: 1616.2 | G7: =F7/Assumptions!$B$7 | H7: =F7*1000*Assumptions!$B$8/1000000 | I7: =H7*(1+Assumptions!$B$9) | J7: 1793 | K7: 3590 | L7: Lagoa dos Ventos is the largest wind complex in South America. Foreign parent, decision may sit in Rome — find out who signs in Brazil before 10 August. | M7: 1) What share of your cut volume was committed to CCEAR-D or CER? 2) What do you owe CCEE in delivery-shortfall ressarcimentos? 3) What is your sobreoferta volume over the window, and what have you assumed it is worth? 4) Are you in any of the twelve suits, or in the ABEEólica/ABSOLAR collective action?
A8: 4 | B8: Central Eólica SPEs (RN/CE) | C8: M | D8: CE,RN | E8: 5 | F8: 1351.4 | G8: =F8/Assumptions!$B$7 | H8: =F8*1000*Assumptions!$B$8/1000000 | I8: =H8*(1+Assumptions!$B$9) | J8: 679.3 | K8: 1166 | L8: Mapped from SIGA ownership. Confirm the group before calling — the SPE names are in the Complexes tab. | M8: 1) What share of your cut volume was committed to CCEAR-D or CER? 2) What do you owe CCEE in delivery-shortfall ressarcimentos? 3) What is your sobreoferta volume over the window, and what have you assumed it is worth? 4) Are you in any of the twelve suits, or in the ABEEólica/ABSOLAR collective action?
A9: 5 | B9: Echoenergia (Equatorial) | C9: H | D9: PI,RN | E9: 2 | F9: 1092.3 | G9: =F9/Assumptions!$B$7 | H9: =F9*1000*Assumptions!$B$8/1000000 | I9: =H9*(1+Assumptions!$B$9) | J9: 338.2 | K9: 702 | L9: ALREADY LITIGATING — two of the twelve cases (1068423-72 and 1068397-74.2024.4.01.3400). CEO Liu Aquino has said publicly some plants hit ~45% restriction, 'patamar que torna a operação insustentável'. They must actively choose to abandon those suits. | M9: 1) What share of your cut volume was committed to CCEAR-D or CER? 2) What do you owe CCEE in delivery-shortfall ressarcimentos? 3) What is your sobreoferta volume over the window, and what have you assumed it is worth? 4) Are you in any of the twelve suits, or in the ABEEólica/ABSOLAR collective action?
A10: 6 | B10: Serena Energia | C10: M | D10: BA,RN | E10: 5 | F10: 1057 | G10: =F10/Assumptions!$B$7 | H10: =F10*1000*Assumptions!$B$8/1000000 | I10: =H10*(1+Assumptions!$B$9) | J10: 725.9 | K10: 1365 | L10: Fitch puts 2025 EBITDA impact at R$200m, 11% of total — the highest proportional hit of any rated name. Listed, so the decision is disclosable and time-pressured. | M10: 1) What share of your cut volume was committed to CCEAR-D or CER? 2) What do you owe CCEE in delivery-shortfall ressarcimentos? 3) What is your sobreoferta volume over the window, and what have you assumed it is worth? 4) Are you in any of the twelve suits, or in the ABEEólica/ABSOLAR collective action?
A11: 7 | B11: Voltalia Brasil | C11: M | D11: BA,CE,PE,PI,RN | E11: 6 | F11: 920.5 | G11: =F11/Assumptions!$B$7 | H11: =F11*1000*Assumptions!$B$8/1000000 | I11: =H11*(1+Assumptions!$B$9) | J11: 822.5 | K11: 1362 | L11: THE ONLY COMPANY THAT HAS BOOKED REAL MONEY — R$175m of curtailment ressarcimento recognised in Q2 2026 results. They understand the mechanism better than anyone. Call them to learn, not to sell. | M11: 1) What share of your cut volume was committed to CCEAR-D or CER? 2) What do you owe CCEE in delivery-shortfall ressarcimentos? 3) What is your sobreoferta volume over the window, and what have you assumed it is worth? 4) Are you in any of the twelve suits, or in the ABEEólica/ABSOLAR collective action?
A12: 8 | B12: Janaúba (Telefônica/Aegea AP) | C12: H | D12: MG | E12: 1 | F12: 628.2 | G12: =F12/Assumptions!$B$7 | H12: =F12*1000*Assumptions!$B$8/1000000 | I12: =H12*(1+Assumptions!$B$9) | J12: 625.2 | K12: 1337 | L12: Self-production structure. Autoprodução is expressly eligible (Termo Cl. 1ª Subcl. 1ª) and its volume is NOT committed to CCEAR-D/CER — so under Cláusula Quinta V it is valued at PLD and PAID IN CASH. This is the profile most likely to produce a real receivable. | M12: 1) What share of your cut volume was committed to CCEAR-D or CER? 2) What do you owe CCEE in delivery-shortfall ressarcimentos? 3) What is your sobreoferta volume over the window, and what have you assumed it is worth? 4) Are you in any of the twelve suits, or in the ABEEólica/ABSOLAR collective action?
A13: 9 | B13: Cutia/União dos Ventos SPEs | C13: M | D13: RN | E13: 3 | F13: 530.9 | G13: =F13/Assumptions!$B$7 | H13: =F13*1000*Assumptions!$B$8/1000000 | I13: =H13*(1+Assumptions!$B$9) | J13: 395.4 | K13: 536 | L13: Mapped from SIGA ownership. Confirm the group before calling — the SPE names are in the Complexes tab. | M13: 1) What share of your cut volume was committed to CCEAR-D or CER? 2) What do you owe CCEE in delivery-shortfall ressarcimentos? 3) What is your sobreoferta volume over the window, and what have you assumed it is worth? 4) Are you in any of the twelve suits, or in the ABEEólica/ABSOLAR collective action?
A14: 10 | B14: Solar MG SPEs | C14: M | D14: MG | E14: 3 | F14: 479.2 | G14: =F14/Assumptions!$B$7 | H14: =F14*1000*Assumptions!$B$8/1000000 | I14: =H14*(1+Assumptions!$B$9) | J14: 715.1 | K14: 1396 | L14: Mapped from SIGA ownership. Confirm the group before calling — the SPE names are in the Complexes tab. | M14: 1) What share of your cut volume was committed to CCEAR-D or CER? 2) What do you owe CCEE in delivery-shortfall ressarcimentos? 3) What is your sobreoferta volume over the window, and what have you assumed it is worth? 4) Are you in any of the twelve suits, or in the ABEEólica/ABSOLAR collective action?
A15: 11 | B15: Elera Renováveis (Brookfield) | C15: H | D15: BA,CE | E15: 2 | F15: 419 | G15: =F15/Assumptions!$B$7 | H15: =F15*1000*Assumptions!$B$8/1000000 | I15: =H15*(1+Assumptions!$B$9) | J15: 392.3 | K15: 693 | L15: ALREADY LITIGATING — two cases over the Alex complex (0800580-25.2024.4.05.8101 and 1087805-51.2024.4.01.3400). Complexo Alex hit 67.7% curtailment in July 2024. Brookfield capital behind it, so the waiver decision will be taken seriously and centrally. | M15: 1) What share of your cut volume was committed to CCEAR-D or CER? 2) What do you owe CCEE in delivery-shortfall ressarcimentos? 3) What is your sobreoferta volume over the window, and what have you assumed it is worth? 4) Are you in any of the twelve suits, or in the ABEEólica/ABSOLAR collective action?
A16: 12 | B16: Serra do Mel solar SPEs | C16: M | D16: RN | E16: 1 | F16: 253.4 | G16: =F16/Assumptions!$B$7 | H16: =F16*1000*Assumptions!$B$8/1000000 | I16: =H16*(1+Assumptions!$B$9) | J16: 245.4 | K16: 433 | L16: Mapped from SIGA ownership. Confirm the group before calling — the SPE names are in the Complexes tab. | M16: 1) What share of your cut volume was committed to CCEAR-D or CER? 2) What do you owe CCEE in delivery-shortfall ressarcimentos? 3) What is your sobreoferta volume over the window, and what have you assumed it is worth? 4) Are you in any of the twelve suits, or in the ABEEólica/ABSOLAR collective action?
... A44: 40 | B44: LAGOA DO BARRO IX ENERGIAS RENOVAVEIS S. (SPE only) | C44: L | D44: PI | E44: 1 | F44: 87.9 | G44: =F44/Assumptions!$B$7 | H44: =F44*1000*Assumptions!$B$8/1000000 | I44: =H44*(1+Assumptions!$B$9) | J44: 113.5 | K44: 296 | L44: Mapped from SIGA ownership. Confirm the group before calling — the SPE names are in the Complexes tab. | M44: 1) What share of your cut volume was committed to CCEAR-D or CER? 2) What do you owe CCEE in delivery-shortfall ressarcimentos? 3) What is your sobreoferta volume over the window, and what have you assumed it is worth? 4) Are you in any of the twelve suits, or in the ABEEólica/ABSOLAR collective action?
B45: TOTAL — named groups above | E45: =SUM(E5:E44) | F45: =SUM(F5:F44) | G45: =SUM(G5:G44) | H45: =SUM(H5:H44) | I45: =SUM(I5:I44) | J45: =SUM(J5:J44) | K45: =SUM(K5:K44)
B47: Confidence: H = corroborated by the company's own disclosure or by a filed lawsuit. M = inferred from SPE naming convention in ANEEL SIGA — plausible, not verified. L = SPE name only, corporate group not established. Do not put an M or L name in front of GC as fact.

Sheet Complexes
A1: Every complex with eligible curtailment, 1 Sep 2023 – 25 Nov 2025
A2: The underlying evidence for the call list. 267 apuração units, 25,326 GWh of REL+CNF curtailment, computed from ONS open data. Sobreoferta (ENE) shown separately because the Portaria never pays for it.
A4: # | B4: Complex | C4: UF | D4: Source | E4: Group / holder | F4: Conf. | G4: Eligible GWh (REL+CNF) | H4: % of pool | I4: Est. claim (R$m) | J4: Sobreoferta GWh (ENE) | K4: Eligible share of cuts | L4: Operating MW | M4: SPE holders in ANEEL SIGA
A5: 1 | B5: SERRA DO MEL B | C5: RN | D5: Wind | E5: Echoenergia (Equatorial) | F5: H | G5: 950.6 | H5: =G5/Assumptions!$B$7 | I5: =G5*1000*Assumptions!$B$8/1000000 | J5: 176.9 | K5: 0.84312021 | L5: 479 | M5: VILA PIAUI 2 EMPREENDIMENTOS E PARTICIPACOES S.A.; VILA PIAUI 1 EMPREENDIMENTOS E PARTICIPACOES S.A.; VILA ALAGOAS II EMPREENDIMENTOS E PARTICIPACOES S.A
A6: 2 | B6: SERRA DO MEL A | C6: RN | D6: Wind | E6: Casa dos Ventos | F6: M | G6: 940.1 | H6: =G6/Assumptions!$B$7 | I6: =G6*1000*Assumptions!$B$8/1000000 | J6: 217 | K6: 0.81246813 | L6: 552 | M6: VENTOS DE VILA CEARA I SPE S.A; VENTOS DE VILA CEARA II SPE S.A; VENTOS DE VILA PARAIBA IV SPE S.A
A7: 3 | B7: CAJU | C7: RN | D7: Wind | E7: Casa dos Ventos | F7: M | G7: 670.7 | H7: =G7/Assumptions!$B$7 | I7: =G7*1000*Assumptions!$B$8/1000000 | J7: 248.6 | K7: 0.72957907 | L7: 686 | M7: VENTOS DE SANTA TEREZA 14 ENERGIAS RENOVAVEIS S.A.; VENTOS DE SANTA TEREZA 01 ENERGIAS RENOVAVEIS S.A.; VENTOS DE SANTA TEREZA 02 ENERGIAS RENOVAVEIS S.A.
A8: 4 | B8: JANAUBA | C8: MG | D8: Solar | E8: Janaúba (Telefônica/Aegea AP) | F8: H | G8: 628.2 | H8: =G8/Assumptions!$B$7 | I8: =G8*1000*Assumptions!$B$8/1000000 | J8: 625.2 | K8: 0.50123236 | L8: 1337 | M8: TELEFONICA BRASIL S.A.; AGUAS DO RIO 4 SPE S.A; Janaúba I Geração Solar Energia S.A.
A9: 5 | B9: MONTE VERDE | C9: RN | D9: Wind | E9: Central Eólica SPEs (RN/CE) | F9: M | G9: 581.4 | H9: =G9/Assumptions!$B$7 | I9: =G9*1000*Assumptions!$B$8/1000000 | J9: 237.2 | K9: 0.71023653 | L9: 418 | M9: CENTRAL EOLICA MONTE VERDE I S.A; CENTRAL EOLICA MONTE VERDE II S.A; CENTRAL EOLICA MONTE VERDE III S.A
A10: 6 | B10: SANTO AGOSTINHO | C10: RN | D10: Wind | E10: Engie Brasil Energia | F10: H | G10: 476.9 | H10: =G10/Assumptions!$B$7 | I10: =G10*1000*Assumptions!$B$8/1000000 | J10: 226 | K10: 0.6784361 | L10: 434 | M10: Eólica Santo Agostinho 1 S.A.; Eólica Santo Agostinho 2 S.A.; Eólica Santo Agostinho 3 S.A.
A11: 7 | B11: SERRA DO MEL II B | C11: RN | D11: Wind | E11: — unmapped — | F11: L | G11: 435.4 | H11: =G11/Assumptions!$B$7 | I11: =G11*1000*Assumptions!$B$8/1000000 | J11: 35.9 | K11: 0.92391249 | L11: 0
A12: 8 | B12: JERUSALEM | C12: RN | D12: Wind | E12: Central Eólica SPEs (RN/CE) | F12: M | G12: 407.2 | H12: =G12/Assumptions!$B$7 | I12: =G12*1000*Assumptions!$B$8/1000000 | J12: 197.1 | K12: 0.67381405 | L12: 260 | M12: CENTRAL EOLICA JERUSALEM I S.A.; CENTRAL EOLICA JERUSALEM II S.A.; CENTRAL EOLICA JERUSALEM III S.A.
A13: 9 | B13: SERRA DO MEL II A | C13: RN | D13: Wind | E13: — unmapped — | F13: L | G13: 402 | H13: =G13/Assumptions!$B$7 | I13: =G13*1000*Assumptions!$B$8/1000000 | J13: 45.1 | K13: 0.89903223 | L13: 0
A14: 10 | B14: RIO DO VENTO | C14: RN | D14: Wind | E14: Casa dos Ventos | F14: M | G14: 388.1 | H14: =G14/Assumptions!$B$7 | I14: =G14*1000*Assumptions!$B$8/1000000 | J14: 370.1 | K14: 0.51190491 | L14: 504 | M14: VENTOS DE SANTA AMÉLIA ENERGIAS RENOVÁVEIS S/A; VENTOS DE SANTO ARTUR ENERGIAS RENOVAVEIS S/A; VENTOS DE SANTA ALICE ENERGIAS RENOVÁVEIS S/A
A15: 11 | B15: LARANJEIRAS | C15: BA | D15: Wind | E15: Serena Energia | F15: M | G15: 382.3 | H15: =G15/Assumptions!$B$7 | I15: =G15*1000*Assumptions!$B$8/1000000 | J15: 270 | K15: 0.58606694 | L15: 505 | M15: CARGILL AGRICOLA S A; ASSURUA 3 I ENERGIA S.A.; ASSURUA 3 II ENERGIA S.A.
A16: 12 | B16: NOVO HORIZONTE | C16: BA | D16: Wind | E16: Casa dos Ventos | F16: M | G16: 349.4 | H16: =G16/Assumptions!$B$7 | I16: =G16*1000*Assumptions!$B$8/1000000 | J16: 228.7 | K16: 0.60442774 | L16: 423 | M16: VENTOS DE SAO TEOFANO ENERGIAS RENOVAVEIS S.A.; VENTOS DE SAO TEONAS ENERGIAS RENOVAVEIS S.A.; VENTOS DE SAO THOMAS ENERGIAS RENOVAVEIS S.A.
A17: 13 | B17: CUMARU | C17: RN | D17: Wind | E17: Enel Green Power Brasil | F17: H | G17: 325.9 | H17: =G17/Assumptions!$B$7 | I17: =G17*1000*Assumptions!$B$8/1000000 | J17: 206.7 | K17: 0.61191937 | L17: 206 | M17: ENEL GREEN POWER CUMARU 01 S.A.; ENEL GREEN POWER CUMARU 05 S.A; ENEL GREEN POWER CUMARU 03 S.A
A18: 14 | B18: RIO DO VENTO EXPANSAO | C18: RN | D18: Wind | E18: Casa dos Ventos | F18: M | G18: 321.9 | H18: =G18/Assumptions!$B$7 | I18: =G18*1000*Assumptions!$B$8/1000000 | J18: 277.7 | K18: 0.53690905 | L18: 534 | M18: VENTOS DE SANTA LÍVIA ENERGIAS RENOVÁVEIS S.A.; VENTOS DE SÃO LUIGI ENERGIAS RENOVÁVEIS S.A.; VENTOS DE SÃO LEOPOLDO ENERGIAS RENOVÁVEIS S.A.
A19: 15 | B19: VISTA ALEGRE - JANAUBA | C19: MG | D19: Solar | E19: Solar MG SPEs | F19: M | G19: 312.5 | H19: =G19/Assumptions!$B$7 | I19: =G19*1000*Assumptions!$B$8/1000000 | J19: 320.6 | K19: 0.4936221 | L19: 768 | M19: VISTA ALEGRE VII ENERGIA SPE LTDA.; CENTRAL FOTOVOLTAICA VISTA ALEGRE XV SPE LTDA.; VISTA ALEGRE I ENERGIA SPE LTDA
A20: 16 | B20: IGAPORA II | C20: BA | D20: Wind | E20: Serena Energia | F20: M | G20: 285.6 | H20: =G20/Assumptions!$B$7 | I20: =G20*1000*Assumptions!$B$8/1000000 | J20: 166.1 | K20: 0.63229781 | L20: 294 | M20: CENTRAIS EOLICAS SERRA DO SALTO LTDA.; CENTRAIS EOLICAS ILHEUS LTDA.; CENTRAIS EOLICAS CANDIBA LTDA.
A21: 17 | B21: MOSSORO II | C21: RN | D21: Wind | E21: Casa dos Ventos | F21: M | G21: 283.3 | H21: =G21/Assumptions!$B$7 | I21: =G21*1000*Assumptions!$B$8/1000000 | J21: 187.5 | K21: 0.60166443 | L21: 408 | M21: USINA DE ENERGIA EOLICA CARCARA I SPE S.A.; USINA DE ENERGIA EOLICA CAICARA I SPE S.A.; USINA DE ENERGIA EOLICA CARCARA II SPE S.A.
A22: 18 | B22: SOL DO SERTAO | C22: BA | D22: Solar | E22: Elera Renováveis (Brookfield) | F22: H | G22: 281.8 | H22: =G22/Assumptions!$B$7 | I22: =G22*1000*Assumptions!$B$8/1000000 | J22: 288.1 | K22: 0.49453287 | L22: 415 | M22: SOL DO SERTAO OB III ENERGIA SOLAR S.A; SOL DO SERTÃO OB I ENERGIA SOLAR LTDA; SOL DO SERTAO OB II ENERGIA SOLAR S.A
A23: 19 | B23: LAGOA DOS VENTOS | C23: PI | D23: Wind | E23: Enel Green Power Brasil | F23: H | G23: 279.6 | H23: =G23/Assumptions!$B$7 | I23: =G23*1000*Assumptions!$B$8/1000000 | J23: 321.9 | K23: 0.46487049 | L23: 717 | M23: ENEL GREEN POWER VENTOS DE SANTA ANGELA 1 S.A.; ENEL GREEN POWER VENTOS DE SANTA ANGELA 2 S.A.; ENEL GREEN POWER VENTOS DE SANTA ANGELA 3 S.A.
A24: 20 | B24: MONTE DO RONCA | C24: RN | D24: Wind | E24: Casa dos Ventos | F24: M | G24: 256 | H24: =G24/Assumptions!$B$7 | I24: =G24*1000*Assumptions!$B$8/1000000 | J24: 183.2 | K24: 0.58291655 | L24: 256 | M24: VENTOS DE SAO FERNANDO I ENERGIA S.A; VENTOS DE SAO FERNANDO II ENERGIA S.A.; VENTOS DE SAO FERNANDO III ENERGIA S.A
A25: 21 | B25: SERRA DO MEL C | C25: RN | D25: Solar | E25: Serra do Mel solar SPEs | F25: M | G25: 253.4 | H25: =G25/Assumptions!$B$7 | I25: =G25*1000*Assumptions!$B$8/1000000 | J25: 245.4 | K25: 0.50804352 | L25: 433 | M25: SOL SERRA DO MEL I SPE S.A; SOL SERRA DO MEL II SPE S.A; SOL SERRA DO MEL V SPE S.A
... A27: 23 | B27: SERRA DO ASSURUA | C27: BA | D27: Wind | E27: Engie Brasil Energia | F27: H | G27: 252.3 | H27: =G27/Assumptions!$B$7 | I27: =G27*1000*Assumptions!$B$8/1000000 | J27: 215.5 | K27: 0.53935965 | L27: 846 | M27: EÓLICA SERRA DO ASSURUÁ 1 LTDA.; EÓLICA SERRA DO ASSURUÁ 2 LTDA.; EÓLICA SERRA DO ASSURUÁ 3 LTDA
A28: 24 | B28: SOL DO CERRADO | C28: MG | D28: Solar | E28: — unmapped — | F28: L | G28: 242 | H28: =G28/Assumptions!$B$7 | I28: =G28*1000*Assumptions!$B$8/1000000 | J28: 276 | K28: 0.46717803 | L28: 681
A29: 25 | B29: ARINOS 2 | C29: MG | D29: Solar | E29: — unmapped — | F29: L | G29: 240.6 | H29: =G29/Assumptions!$B$7 | I29: =G29*1000*Assumptions!$B$8/1000000 | J29: 452.8 | K29: 0.34699689 | L29: 0
A30: 26 | B30: MORRO DO CHAPEU SUL II | C30: BA | D30: Wind | E30: Enel Green Power Brasil | F30: H | G30: 232.6 | H30: =G30/Assumptions!$B$7 | I30: =G30*1000*Assumptions!$B$8/1000000 | J30: 209.6 | K30: 0.52591922 | L30: 353 | M30: ENEL GREEN POWER VENTOS DE SANTA ESPERANCA 15 S.A.; ENEL GREEN POWER VENTOS DE SANTA ESPERANÇA 16 S.A.; ENEL GREEN POWER VENTOS DE SANTA ESPERANÇA 17 S.A.
A31: 27 | B31: AFONSO BEZERRA | C31: RN | D31: Wind | E31: Cutia/União dos Ventos SPEs | F31: M | G31: 225.5 | H31: =G31/Assumptions!$B$7 | I31: =G31*1000*Assumptions!$B$8/1000000 | J31: 97.1 | K31: 0.69894978 | L31: 160 | M31: AFONSO BEZERRA I GERACAO DE ENERGIA SPE S.A; AFONSO BEZERRA II GERACAO DE ENERGIA SPE S.A; AFONSO BEZERRA III GERACAO DE ENERGIA SPE S.A.
A32: 28 | B32: CUTIA | C32: RN | D32: Wind | E32: Cutia/União dos Ventos SPEs | F32: M | G32: 219.8 | H32: =G32/Assumptions!$B$7 | I32: =G32*1000*Assumptions!$B$8/1000000 | J32: 254.3 | K32: 0.46360606 | L32: 313 | M32: USINA DE ENERGIA EOLICA GUAJIRU S/A; USINA DE ENERGIA EOLICA JANGADA S/A; USINA DE ENERGIA EOLICA CUTIA S/A
A33: 29 | B33: JAIBA V | C33: MG | D33: Solar | E33: Jaíba V (Sendas/Assaí AP) | F33: H | G33: 209.8 | H33: =G33/Assumptions!$B$7 | I33: =G33*1000*Assumptions!$B$8/1000000 | J33: 240.5 | K33: 0.46585961 | L33: 500 | M33: SENDAS DISTRIBUIDORA S/A; Jaíba CN Energias Renováveis S.A.; Jaíba CE Energias Renováveis S.A.
A34: 30 | B34: SERRA DA BABILONIA | C34: BA | D34: Wind | E34: Serra da Babilônia / BA SPEs | F34: M | G34: 207.5 | H34: =G34/Assumptions!$B$7 | I34: =G34*1000*Assumptions!$B$8/1000000 | J34: 177.3 | K34: 0.53926454 | L34: 505 | M34: EOLICA SERRA DA BABILONIA II S.A; EOLICA SERRA DA BABILONIA IX S.A; EOLICA SERRA DA BABILONIA VI S.A
A35: 31 | B35: VENTOS SANTA EUGENIA | C35: BA | D35: Wind | E35: — unmapped — | F35: L | G35: 206.3 | H35: =G35/Assumptions!$B$7 | I35: =G35*1000*Assumptions!$B$8/1000000 | J35: 128.5 | K35: 0.61625583 | L35: 0
A36: 32 | B36: BELMONTE | C36: PE | D36: Solar | E36: Belmonte (Mateus Supermercados AP) | F36: H | G36: 204.2 | H36: =G36/Assumptions!$B$7 | I36: =G36*1000*Assumptions!$B$8/1000000 | J36: 243.7 | K36: 0.45595059 | L36: 455 | M36: MATEUS SUPERMERCADOS S.A.; BELMONTE 1.1. PARQUE SOLAR S.A.; BELMONTE 1.2. PARQUE SOLAR S.A.
A37: 33 | B37: UMBURANAS | C37: BA | D37: Wind | E37: Engie Brasil Energia | F37: H | G37: 202.7 | H37: =G37/Assumptions!$B$7 | I37: =G37*1000*Assumptions!$B$8/1000000 | J37: 205.3 | K37: 0.49679261 | L37: 360 | M37: EOLICA UMBURANAS 5 S.A.; EOLICA UMBURANAS 1 S.A.; EOLICA UMBURANAS 2 S.A.
A38: 34 | B38: CAMPO LARGO | C38: BA | D38: Wind | E38: Engie Brasil Energia | F38: H | G38: 198.3 | H38: =G38/Assumptions!$B$7 | I38: =G38*1000*Assumptions!$B$8/1000000 | J38: 275.8 | K38: 0.41826949 | L38: 688 | M38: CLWP EOLICA PARQUE III S.A.; CLWP EOLICA PARQUE IV S.A.; CLWP EOLICA PARQUE V S.A.
A39: 35 | B39: ARACAS | C39: BA | D39: Wind | E39: CENTRAIS EOLICAS VENTOS DO NORDESTE S/A (SPE only) | F39: L | G39: 195.8 | H39: =G39/Assumptions!$B$7 | I39: =G39*1000*Assumptions!$B$8/1000000 | J39: 107.9 | K39: 0.64476553 | L39: 168 | M39: CENTRAIS EOLICAS VENTOS DO NORDESTE S/A; CENTRAIS EOLICAS DA PRATA S.A; Centrais Eólicas dos Araçás S.A
A40: 36 | B40: BRISA POTIGUAR I | C40: RN | D40: Wind | E40: Casa dos Ventos | F40: M | G40: 193.7 | H40: =G40/Assumptions!$B$7 | I40: =G40*1000*Assumptions!$B$8/1000000 | J40: 126.9 | K40: 0.60415918 | L40: 184 | M40: NOVA ASA BRANCA I ENERGIAS RENOVAVEIS S.A; NOVA EURUS IV ENERGIAS RENOVAVEIS S.A; NOVA ASA BRANCA II ENERGIAS RENOVAVEIS S.A
A41: 37 | B41: SANTA CLARA | C41: RN | D41: Wind | E41: Voltalia Brasil | F41: M | G41: 192.1 | H41: =G41/Assumptions!$B$7 | I41: =G41*1000*Assumptions!$B$8/1000000 | J41: 135.8 | K41: 0.58594372 | L41: 188 | M41: SANTA CLARA I ENERGIAS RENOVAVEIS LTDA; SANTA CLARA III ENERGIAS RENOVAVEIS LTDA; SANTA CLARA VI ENERGIAS RENOVAVEIS LTDA
A42: 38 | B42: FUTURA | C42: BA | D42: Solar | E42: Solar BA SPEs | F42: M | G42: 189.4 | H42: =G42/Assumptions!$B$7 | I42: =G42*1000*Assumptions!$B$8/1000000 | J42: 312.6 | K42: 0.37727168 | L42: 692 | M42: SPE FUTURA 4 GERACAO E COMERCIALIZACAO DE ENERGIA SOLAR S.A.; SPE FUTURA 1 GERACAO E COMERCIALIZACAO DE ENERGIA SOLAR S.A.; SPE FUTURA 2 GERACAO E COMERCIALIZACAO DE ENERGIA SOLAR S.A.
...

Sheet Contacts
A1: Named contacts — verified from the public record only
A2: Nobody on this sheet is a guess. Where a name could not be verified it has been left out rather than invented.
A4: Name | B4: Role | C4: Organisation | D4: Conf. | E4: What is on the record | F4: Why this call
A5: THE TWO CALLS THAT ARE WORTH MORE THAN ANY GENERATOR
A6: Elbia Gannoum | B6: CEO / Presidente-executiva | C6: ABEEólica | D6: H | E6: Speaks for ~40 member companies. Source of the ~R$6bn CCEE passivo figure. Has publicly refused to forecast take-up: 'Não posso garantir aqui que haverá adesão de 100%, nem de 50%.' | F6: One call reaches the whole membership. She is also the person who knows which members are wavering.
A7: Donato da Silva Filho | B7: CEO / Diretor-geral | C7: Volt Robotics | D7: H | E7: Near-monopoly supplier of the sector's curtailment loss data — every R$ figure in the Brazilian press traces to him. Tested MME's SOSIN formula and found it produces 143% MORE sobreoferta than ONS's own calculation. | F7: PARTNER OR COMPETITOR. He has the classification data and the credibility; he does not have capital. That is a complementary pairing, and it is the single highest-value call on this sheet.
A8: NAMED IN THE PUBLIC RECORD ON CURTAILMENT — these people have self-identified as caring
A9: Liu Aquino | B9: CEO | C9: Echoenergia (Equatorial) | D9: H | E9: Publicly: some plants at ~45% restriction, 'patamar que torna a operação insustentável'. Company is plaintiff in two of the twelve suits. | F9: Already litigating — must actively choose to abandon.
A10: Bernardo Bezerra | B10: Diretor de Regulação e Inovação | C10: Serena Energia | D10: H | E10: Ex-PSR. Writes publicly on cut classification (eixos, 13 Apr 2026, 'Curtailment: separando o joio do trigo'). | F10: The most technically credible regulatory director in the sector on precisely this issue.
A11: Gabriel Mann | B11: Diretor de Regulação | C11: Engie Brasil Energia | D11: M | E11: Quoted updating Engie's curtailment projection to 25% for 2025. | F11: Engie discloses percentages but has never published an R$ figure.
A12: Gustavo Estrella | B12: CEO | C12: CPFL Energia | D12: H | E12: Quoted on the step-change: 'Na média do semestre, tivemos um curtailment de 8,6% no ano passado, e nesse começo de ano, 20,9%.' | F12: CPFL is the most transparent discloser — R$558m FY2025 lost revenue, 30.8% curtailment.
A13: Isabella Sene | B13: Regulatory lead | C13: ABSOLAR | D13: M | E13: Source of the R$2.8bn centralised-solar ACR figure for 2025. ABSOLAR has stated the manifestação de interesse does not itself waive existing suits. | F13: The solar counterpart to ABEEólica.
A14: Francisco Silva | B14: Regulatory | C14: ABEEólica | D14: M | E14: Source of the R$2.5bn non-reimbursable sobreoferta figure. | F14: Has already quantified the waived side.
A15: Rui Altieri | B15: Chairman | C15: APINE | D15: M | E15: Put the 2025 cost of curtailment at R$6bn. | F15: Independent producers' association — reaches the mid-caps.
A16: REGULATORY AND OFFICIAL
A17: Agnes Maria de Aragão da Costa | B17: Diretora | C17: ANEEL | D17: H | E17: Authored the January 2026 medida cautelar suspending REN 1.030 reapurações (Processo 48500.000231/2026-56). Her voto is the authoritative source for the 46/41/13 classification split. | F17: Not a sales call. Read her voto before any regulatory conversation.
A18: ADVISERS ALREADY PUBLISHING ON PORTARIA 140
A19: Raphael Gomes | B19: Partner, energy regulatory | C19: Lefosse | D19: H | E19: Published a client alert on Portaria 140. Quoted: 'Com a tratativa atual, podemos ter mais uma onda de judicialização.' | F19: Already advising on this. Either a co-counsel or the competition — worth knowing which.
A20: (Mattos Filho energy team) | B20: — | C20: Mattos Filho | D20: M | E20: Published a Portaria 140 client alert. | F20: Same.
A21: THINK TANKS AND CONSULTANCIES WITH PUBLISHED POSITIONS
A22: Eduardo Müller Monteiro | B22: — | C22: Instituto Acende Brasil | D22: H | E22: Presented to the Senate CI hearing 30 Sep 2025. Best-documented independent methodology: R$3.85bn all cuts at PLD, R$2.85bn for the compensable subset. | F22: The most rigorous public work on sizing. Read it before modelling.
A23: João Carlos Mello | B23: — | C23: Thymos Energia | D23: M | E23: Argues PLD/CMO at R$200–300/MWh during oversupply is itself the distortion. Publishes no R$ tally. | F23: Useful on the price mechanics.
A24: Jean Paul Prates | B24: Chairman | C24: Cerne | D24: H | E24: Ex-Petrobras CEO. Cerne/CarpeVie put losses above R$5bn, 70% in the Nordeste. | F24: Political reach as much as technical.
A25: HOW TO USE THIS SHEET
A26: No email addresses are given here | B26: — | C26: — | D26: — | E26: Every name above is sourced from a published quote, filing or IR page. NO EMAIL ADDRESS HAS BEEN CONSTRUCTED OR GUESSED — the Apollo database returned a billing error on this account, so nothing here comes from a contact database. | F26: Route in through GC's network rather than cold email. For the ones with no route, the association call (Gannoum, Sene) is the way in.
A27: Company CFOs and GCs are deliberately not listed | B27: — | C27: — | D27: — | E27: A separate agent was still searching IR pages and CVM filings when this was built. Rather than pad the sheet with guessed names, the roles are left for GC to fill from his own network — which is faster and more accurate than anything scraped. | F27: The five names at the top of this sheet are enough to start.

Sheet Assumptions
A1: Assumptions and method
A2: Yellow cells are inputs. Everything else is a formula. Read the second block before quoting any number.
A4: Input | B4: Value | C4: Unit | D4: Basis, and how much to trust it
A5: INPUTS — edit the yellow cells; every estimate on the other tabs recalculates
A6: Compensation pool, Portaria 140 window | B6: 3300 | C6: R$ m | D6: MME's own estimate as reported 21–23 Jul 2026. Volt Robotics says R$2,700m; ABEEólica R$3,300m; Folhapress reports MME at R$3,490m. NO PRIMARY DOCUMENT STATES ANY FIGURE — the Portaria itself sets no pool.
A7: Eligible curtailment in the window | B7: 25326 | C7: GWh | D7: COMPUTED, not sourced. Built from ONS half-hourly constrained-off open data for 1 Sep 2023 – 25 Nov 2025, counting only REL (indisponibilidade externa) and CNF (confiabilidade elétrica). Excludes ENE (sobreoferta), which the Portaria does not pay for.
A8: Implied compensation price | B8: =B6/B7*1000 | C8: R$/MWh | D8: =pool / eligible volume. Sits between the PLD floor (R$57.31 in 2026) and ACR contract prices, so the pool estimates are internally coherent.
A9: IPCA uplift, event date to payment | B9: 0.22 | C9: % | D9: EDITABLE. Art. 6º §1º indexes from each event date to actual payment. Events run Sep 2023–Nov 2025; payment late 2027–H1 2028. A rough 22% assumes ~4.5%/yr over ~4.4 years average. Replace with a proper monthly IPCA build before pricing anything.
A10: Sutphin fee on an advisory mandate | B10: 0.015 | C10: % | D10: EDITABLE. Illustrative only. No mandate has been signed and no fee has been discussed with anyone.
A12: WHAT THIS MODEL DELIBERATELY DOES NOT DO
A13: It does not split cash from book entry
A14: It does not net against what they owe CCEE
A15: It does not price the waiver
A16: It does not value the garantia física loss
A17: It uses one price for everyone

Sheet Portaria 140 - Mechanics
A1: Portaria Normativa MME nº 140/2026 — what it actually says
A2: Everything below is from the primary text in the DOU of 21 July 2026. Article references are exact. Where the Portaria is silent, this sheet says so rather than filling the gap.
A4: Point | B4: Position | C4: Detail and article reference
A5: THE INSTRUMENT
A6: Citation | B6: Portaria Normativa MME nº 140, de 18 de julho de 2026 | C6: DOU 21/07/2026, Ed. 135-A, Seção 1 – Extra A, p. 10. 12 articles + Anexo (minuta do Termo).
A7: Statutory basis | B7: Art. 1º-B, Lei 10.848/2004, inserted by Lei 15.269/2025 | C7: Lei 15.269/2025 published DOU 25.11.2025, in force on publication — which is what fixes the window's end date.
A8: Instrument created | B8: Termo de Compromisso | C8: Not a termo de adesão, not a transação, not a reconhecimento de dívida.
A9: Parties | B9: A UNIÃO, via MME (Poder Concedente) + the GERADOR | C9: CCEE is NOT a party — it is the operational agent. ENBPar is interveniente for Proinfa only.
A10: Legal nature | B10: Título executivo extrajudicial (Cl. 11ª, art. 784 II and III, CPC) | C10: Directly enforceable against the União. Forum: Justiça Federal, Seção Judiciária do DF. No arbitration.
A11: Hierarchy | B11: Termo > Portaria 140 > CCEE Procedimentos e Regras de Comercialização | C11: Termo, Cl. 5ª, Subcl. 4ª. Matters if CCEE's rules end up narrower than the Termo.
A12: DATES
A13: ELECTION DEADLINE | B13: 10 AUGUST 2026 | C13: Art. 2º I — 20 days from publication on 21.07.2026. NOTE: the weekend roll-forward in arts. 4º §4º and 5º §9º does NOT apply to art. 2º. It lands on a Monday, so the point is moot — but assume no elasticity.
A14: Curtailment window compensated | B14: 1 Sep 2023 to 25 Nov 2025, inclusive | C14: Art. 1º, parágrafo único. End date = entry into force of art. 1º-B.
A15: CCEE adapted rules due | B15: ~19 Sep 2026 | C15: Art. 7º §1º — 60 days.
A16: ONS calculation tool + cronograma | B16: ~18 Nov 2026 | C16: Art. 5º §1º I — 120 days.
A17: ONS final database to CCEE | B17: ~27 Apr 2027 | C17: Chain of art. 5º deadlines.
A18: Convocação to sign | B18: Cannot issue before the above | C18: Art. 2º §3º.
A19: CCEE publishes cut volumes | B19: ~27 May 2027 | C19: Art. 5º §8º.
A20: PAYMENT | B20: Late 2027 base case; H1 2028 on the outer limits | C20: Art. 6º §2º — 180 days from the first business day after the signature deadline. The Portaria fixes NO calendar date, only a chain of relative deadlines.
A21: WHO IS ELIGIBLE
A22: Sources | B22: Wind and solar FOTOVOLTAICA only | C22: Art. 1º. CSP/heliotérmica is not covered by the wording.
A23: Connection | B23: Rede Básica and DITs no âmbito da distribuição | C23: VIRES POINT: the statute says only 'conectada ao SIN'. The Portaria narrows it, arguably excluding SIN-connected plants on non-DIT distribution assets.
A24: Who holds the right | B24: Titular de usina com outorga — the grant holder, not the offtaker
A25: Contract regime | B25: ACR, ACL and autoprodução are ALL eligible | C25: Termo Cl. 1ª Subcl. 1ª — compensation is due 'independentemente do ambiente ou da modalidade de contratação', with no garantia física cap, no contracted-volume cap, and no frequency or duration threshold.
A26: Thresholds | B26: None — no MW floor, no COD cut-off, no minimum curtailment volume
A27: WHAT IS PAID FOR
A28: Indisponibilidade externa | B28: COMPENSATED — 100%, no haircut | C28: Termo Cl. 2ª.
A29: Confiabilidade elétrica | B29: COMPENSATED — 100%, no haircut | C29: Termo Cl. 3ª.
A30: Sobreoferta de energia | B30: NOT COMPENSATED | C30: Termo Cl. 1ª Subcl. 2ª. This is the majority of curtailed volume and it is the commercial heart of the problem.
A31: Mixed hours | B31: Indisponibilidade externa prevails, then confiabilidade; sobreoferta loses | C31: Art. 5º §5º. Generator-favourable tie-break.
A32: Own-asset carve-out | B32: Curtailment traced to the generator's own or shared connection assets is NOT compensated | C32: Termo Cl. 2ª/3ª, Subcl. 2ª/3ª.
A33: Set-off | B33: Amounts already received under existing rules are deducted | C33: Termo Cl. 5ª Subcl. 1ª VII.
A34: HOW IT IS VALUED — THE WATERFALL
A35: Step 1 — CCEAR-D / CER commitments | B35: DEBT RELIEF, NOT CASH | C35: Cl. 5ª Subcl. 1ª III: curtailed MWh are treated as energy DELIVERED against CCEAR-D and CER commitments, reducing the generator's delivery-shortfall ressarcimentos. No money moves.
A36: Step 2 — residual contracted | B36: Valued on the respective contract terms | C36: Cl. 5ª Subcl. 1ª IV.
A37: Step 3 — UNCONTRACTED volume | B37: CASH, at PLD of the plant's submarket | C37: Cl. 5ª Subcl. 1ª V: 'deverá ser repassada ao GERADOR'. THIS IS THE ONLY TRANCHE THAT PRODUCES A RECEIVABLE ANYONE CAN BUY.
A38: Step 4 — Proinfa | B38: At the Proinfa contract price in force at the date of the cut, paid via ENBPar | C38: Cl. 5ª Subcl. 1ª VI; Art. 9º.
A39: Indexation | B39: IPCA, from the date of EACH curtailment event to actual payment | C39: Art. 6º §1º. Runs from 2023–2025 event dates, so the accrued uplift by payment is substantial.
A40: Interest | B40: SILENT — no juros, no mora, no Selic anywhere in the text | C40: Monetary correction only.
A41: MCP default-sharing | B41: CARVED OUT — credits do not participate in the rateio da inadimplência | C41: Art. 6º §6º, unambiguous. The generator does not bear other agents' defaults on this amount.
...

Sheet Call Script
A1: Call script — the two weeks to 10 August 2026
A2: Advisory first, capital second. The instrument is irrevocable, so the advice is genuinely valuable and genuinely scarce.
B4: What to say
A5: THE SINGLE MOST IMPORTANT THING TO UNDERSTAND — AND ALMOST NOBODY HAS
B6: There are TWO decisions, ten months apart, and they are constantly being confused with each other. The 10 August manifestação de interesse is NOT the waiver. ABSOLAR has said so publicly: filing the manifestation does not bind anyone to drop a lawsuit. The irrevocable renúncia happens at SIGNATURE of the Termo — and the convocação to sign cannot legally issue until ONS finishes its database around late April 2027. Signature therefore lands mid-2027, by which point CCEE has published the actual volumes. So filing by 10 August is cheap optionality and almost everyone should do it. The real decision is ten months later, with the numbers in hand. Anyone telling a generator to agonise over 10 August has misread the instrument.
A7: What this does to the engagement | B7: It is not a two-week campaign. It is a ten-month advisory position — a free and easy first call now, then the classification audit, then the ONS contestation window around March 2027, then the signature decision in mid-2027. That is a far better business than a fortnight of cold calls.
A8: THE OPENING — 20 SECONDS
A9: Say this | B9: "You have until 10 August to file the manifestação under Portaria 140. I am not calling to sell you anything. I am calling because most people are treating 10 August as the decision, and it is not — the waiver does not bite until you sign, and that is mid-2027. What matters between now and then is whether your cut hours are correctly classified, and almost nobody is auditing that."
A10: Why it works | B10: It is a date, it is true, and it tells them within one sentence that you have read the instrument rather than a law firm summary.
A11: THE FOUR THINGS ACTUALLY WORTH MONEY TO THEM
A12: 1 — The classification is a black box, and it decides everything | B12: "Whether an hour is coded confiabilidade or sobreoferta decides whether you are paid for it. Volt Robotics tested MME's SOSIN formula and found it produces 143 per cent more sobreoferta than ONS's own calculation. The share coded non-compensable has gone from 27 per cent in 2023 to 65 per cent in the first half of 2026. There is a ten-day contestation window after ONS's consistency analysis, around March 2027. Every point you move from sobreoferta to confiabilidade is cash. Is anyone re-running your hours?"
A13: 2 — Nobody knows which PLD applies | B13: "Cláusula Quinta values your uncommitted volume at PLD — but the Termo never says whether that is the PLD at the time of the cut or at the date of compensation. Lefosse have flagged it. Nordeste PLD sat at the R$58 floor for most of early 2025 and averaged R$227 across 2026. On a large book that ambiguity is worth nine figures. It should be resolved before you sign, not after."
A14: 3 — Signing turns a suspended liability into an enforceable one | B14: "This is the one that gets missed. Cláusula Oitava: on signing you authorise CCEE to resume billing the CCEAR-D and CER ressarcimentos you owe, and you undertake not to oppose provisional orders against the União or CCEE. If a court decision is currently the only thing keeping a nine-figure CCEE liability off your books, you are converting it into an enforceable debt today, against a credit that pays in late 2027. That trade has to be modelled, not assumed."
A15: 4 — But the near-term carrot is real, and it is not the credit | B15: "Article 6 paragraph 3: file the manifestação and CCEE's settlement of what you owe under CER and CCEAR-D stays suspended through the whole process. For anyone tight on cash that is worth more right now than the compensation itself. It is also why filing by 10 August is close to free."
A16: THE TWO STRUCTURAL POINTS TO HAVE READY
A17: Most of it is not cash | B17: Cláusula Quinta treats curtailed MWh as delivered against CCEAR-D and CER first, which cancels a debt rather than paying anyone. Only uncommitted volume is paid at PLD. Sector-wide, ~R$3.3bn of credit nets against ~R$6bn owed, so generators stay net owing even after full compensation. ASK WHICH SIDE THEY ARE ON — it cannot be worked out from outside, and that is exactly why the question opens the conversation.
A18: The veto is still alive | B18: The vetoed art. 1º-A would have compensated all externally-caused cuts except sobreoferta, retroactively. Congress pulled the override from the agenda on 18 June 2026 and has still not voted it. The Termo's waiver is bounded by event date, not by which law creates the right — so signing surrenders that option for nothing.
A19: WHAT YOU ARE OFFERING ON CALL ONE
A20: The offer | B20: Re-run their curtailment hours against ONS's own classification and tell them what share is being coded sobreoferta that should not be — plus the two-sided number: what the Portaria pays them, split cash versus debt relief, against what the waiver and the garantia física revision cost them. We have already built the eligible-volume base for all 267 complexes in the country from ONS open data, so their line already exists.
A21: Price it or not? | B21: Free for the priority names. The analysis is what earns the right to the 2027 conversation, and that is where capital goes to work.
A22: WHAT YOU DO NOT SAY ON CALL ONE
A23: Do not | B23: Do not offer to buy the credit. There is no Termo, no quantified amount and no título executivo until mid-2027. There is literally nothing to buy yet.
A24: Do not | B24: Do not claim the credit is assignable. The Portaria contains zero occurrences of cessão, transferência, oneração, penhor or caução. It is silent. If asked directly, say exactly that.
A25: Do not | B25: Do not quote R$3.3bn as fact. No primary document states any pool figure, and MME says the values are not yet defined.
A26: Do not | B26: Do not tell them whether to sign. You are quantifying both sides. For most of them the honest answer today is: file in August, audit your classification in between, decide in 2027.
A27: WHERE THE CAPITAL ACTUALLY GOES
A28: Not the holdcos | B28: Casa dos Ventos holds the largest eligible claim in the country and does not need us — it raised US$1.1bn in a US private placement in June 2026. Essentia is buying assets, not selling claims. Call them for information and relationship, not for a financing.
A29: The project-finance SPEs — this is the population | B29: Fitch put 13 Brazilian renewable project financings on Rating Watch Negative in October 2025 explicitly on curtailment, downgraded 6 by May 2026, and left 11 on negative outlook with pressure projected to persist to 2030. Tupi (BRL 820m, sponsor Ibitu, PPAs with Cemig GT) runs a minimum DSCR of 1.03x and cannot distribute below 1.25x. ENGIE's São Pedro IV averages 0.75x. These vehicles cannot wait until 2028 and cannot pay a dividend in the meantime. That is where a bridge is worth something.
A30: The one acute name | B30: Rio Alto: extrajudicial recovery extinguished without resolution in June 2026, BTG enforcing Santa Luzia 5, 7 and 9, a sale mandated to close by end-2026 with no buyer, Coremas averaging 52 per cent restricted and Santa Luzia 35.8 per cent. It cannot survive to late 2027 on this credit. Whatever the right answer is there, it is not a bridge loan.
A31: Also worth knowing | B31: BNDES opened case-by-case debt standstills for curtailment-hit projects in October 2025, with parallel talks at BNB and Banco do Brasil. Atlas Renewable Energy suspended roughly 1.5 GW and US$1bn of Brazilian projects in June 2026 explicitly over curtailment. The distress is real and it is being managed quietly.
A32: HANDLING THE OBVIOUS PUSHBACKS
A33: "Our lawyers are on it" | B33: "Only Lefosse and Mattos Filho have published anything on this, and nobody has filed a request for clarification in the days since publication. Ask your lawyers one question: which PLD applies to our uncommitted volume — the date of the cut, or the date of payment? If they have an answer, you do not need me."
A34: "ABEEólica is handling it" | B34: "Elbia Gannoum has said publicly she cannot guarantee adhesion of 100 per cent or of 50 per cent. And the Termo excludes you from the collective action individually, by name. Whether that trade works for you depends on your contract mix and your classification split, and no association can answer that member by member."
A35: "Why do you care?" | B35: "We finance receivables against solvent obligors in Brazil. This creates a large one with a two-year wait attached. The fastest way to understand it properly is to work through real books with people who own the assets. If something commercial follows later, it follows later."
A36: "Send me a deck" | B36: "I would rather send you your own numbers. We have already built the eligible-volume base for every complex in the country from ONS data. Tell me which complexes are yours and you will have your own line by the end of the week."

Sheet Sources
A1: Sources
A2: Everything in this workbook is traceable to a row below. Where a figure could not be traced to a primary document, the workbook says so.
A4: Source | B4: What it gives you, and any caveat | C4: Link
A5: PRIMARY — THE INSTRUMENT
A6: Portaria Normativa MME nº 140, de 18 de julho de 2026 | B6: DOU 21/07/2026, Ed. 135-A, Seção 1 Extra A, p.10 | C6: https://www.in.gov.br/web/dou/-/portaria-normativa-mme-n-140-de-18-de-julho-de-2026-720529777
A7: MME release on the Portaria | B7: gov.br/mme | C7: https://www.gov.br/mme/pt-br/assuntos/noticias/mme-regulamenta-procedimentos-para-celebracao-de-termo-de-compromisso-sobre-compensacao-por-cortes-de-geracao
A8: CELEBRA — the election portal | B8: Where the manifestação de interesse is filed by 10 Aug 2026 | C8: https://celebra.mme.gov.br/
A9: Lei 10.848/2004, art. 1º-B | B9: Inserted by Lei 15.269/2025 — the statutory basis | C9: https://www.planalto.gov.br/ccivil_03/_ato2004-2006/2004/lei/l10.848.htm
A10: Lei 15.269/2025 | B10: Sanctioned 24 Nov 2025, published 25 Nov 2025 | C10: https://www.planalto.gov.br/ccivil_03/_ato2023-2026/2025/lei/L15269.htm
A11: Veto message VEP-1755-25 | B11: The vetoed art. 1º-A — STILL NOT VOTED BY CONGRESS | C11: https://www.planalto.gov.br/ccivil_03/_ato2023-2026/2025/Msg/Vep/VEP-1755-25.htm
A12: ANEEL Voto, Proc. 48500.000231/2026-56 | B12: Diretora Agnes Maria de Aragão da Costa, Jan 2026. Authoritative source for the 46% ENE / 41% CNF / 13% REL split | C12: https://canalsolar.com.br/wp-content/uploads/2026/01/voto.pdf
A13: DATA — COMPUTED FOR THIS ANALYSIS
A14: ONS constrained-off, wind, per apuração unit | B14: Half-hourly, Oct 2021 → Jul 2026, CC-BY. The eligible-claim column is built from this. | C14: https://dados.ons.org.br/dataset/restricao_coff_eolica_usi
A15: ONS constrained-off, wind, per plant | B15: 1,053 individual plants with CEG — the ownership join | C15: https://dados.ons.org.br/dataset/restricao_coff_eolica_detail
A16: ONS constrained-off, solar | B16: SERIES STARTS APRIL 2024 — there is no public solar curtailment data before that | C16: https://dados.ons.org.br/dataset/restricao_coff_fotovoltaica
A17: ANEEL SIGA | B17: Ownership and capacity by CEG. 98.9% of the CEGs in the ONS detail files matched. | C17: https://dadosabertos.aneel.gov.br/dataset/siga-sistema-de-informacoes-de-geracao-da-aneel
A18: CCEE — encargo received per agent and per plant | B18: Includes an ENCARGO_CONSTRAINED_OFF column, monthly 202311→202605 | C18: https://dadosabertos.ccee.org.br/dataset/encargo_recebido_perfil_agente_usina
A19: CCEE PLD | B19: Nordeste monthly average: 2024 R$118.34 · 2025 R$176.60 · 2026 YTD R$226.63. Floor 2026 R$57.31. | C19: https://dadosabertos.ccee.org.br/dataset/pld_horario
A20: SIZING — THE COMPETING ESTIMATES
A21: MME ~R$3.3bn netted against ~R$6bn owed to CCEE | B21: Poder360, 22 Jul 2026. NO PRIMARY DOCUMENT STATES ANY POOL FIGURE. | C21: https://www.poder360.com.br/poder-governo/governo-regulamenta-acordo-de-r-33-bi-com-usinas-renovaveis/
A22: Volt Robotics — R$2.7bn compensable; classification is a black box | B22: eixos / MegaWhat, 23 Jul 2026. Found MME's SOSIN formula produces 143% more sobreoferta than ONS's own method. | C22: https://eixos.com.br/politica/volt-robotics-estima-ressarcimento-por-cortes-de-geracao-em-r-27-bilhoes-e-aponta-falta-de-clareza-na-classificacao/
A23: Instituto Acende Brasil — R$3.85bn all cuts at PLD, R$2.85bn compensable | B23: Senate CI hearing, 30 Sep 2025. Best-documented independent methodology. | C23: https://acendebrasil.com.br/wp-content/uploads/2025/09/20250930_AcendeBr_AP_CI_Senado_Curtailment_rev_3-1.pdf
A24: Volt Robotics — 2025 balanço: R$6.5bn, 20.6% of available generation | B24: Jan 2026 | C24: https://cenarioenergia.com.br/wp-content/uploads/2026/01/VoltRobotics_AnaliseCurtailment_Balanco-2025_Janeiro-2026.pdf
A25: Fitch per-company 2025 EBITDA impact | B25: Auren R$400m · Serena R$200m · Engie Brasil R$150m. Via NeoFeed, 25 Feb 2026. | C25: https://neofeed.com.br/negocios/brasil-desperdica-20-de-sua-energia-renovavel-e-gera-prejuizos-bilionarios-a-empresas-do-setor-eletrico/
A26: LITIGATION
A27: The census of twelve suits, with process numbers | B27: MegaWhat, 31 Oct 2024. None had obtained a liminar. | C27: https://megawhat.energy/geracao/aneel-ja-e-alvo-de-12-acoes-judiciais-por-curtailment/
A28: STJ suspends the one TRF1 injunction | B28: SLS 3.546, Min. Herman Benjamin, Jan 2025 | C28: https://www.arandanet.com.br/revista/em/noticia/10214-Aneel-consegue-suspender-liminar-do-constrained-off-no-STJ.html
A29: Congress removes the veto override from the agenda | B29: Canal Solar, 17 Jun 2026 — STILL UNVOTED as at 26 Jul 2026 | C29: https://canalsolar.com.br/congresso-analisa-vetos-regras-gd-eolicas-offshore/
A30: Industry expects continuing litigation | B30: eixos, 23 Jul 2026 | C30: https://eixos.com.br/energias-renovaveis/portaria-traz-alivio-mas-nao-encerra-judicializacao-sobre-cortes-de-geracao-avaliam-geradores-e-especialistas/
A31: COMPANY DISCLOSURE
A32: Voltalia books R$175m of curtailment ressarcimento in Q2 2026 | B32: THE FIRST REALISED COMPENSATION FIGURE IN THE MARKET. MegaWhat, 23 Jul 2026. | C32: https://megawhat.uol.com.br/economia-e-politica/resultados/voltalia-contabiliza-r-175-mi-em-ressarcimento-do-curtailment-no-resultado-do-2o-tri/
A33: CPFL FY2025 — R$558m lost revenue, 30.8% curtailment | B33: CPFL 4T25 release. The most transparent disclosure in the sector. | C33: https://ri.cpfl.com.br/
A34: Engie 4T25 — curtailment in percentages only, no R$ | B34: Worst assets: Santo Agostinho 36%, Trairi 31%, Campo Largo 17%, Serra do Assuruá 14% | C34: https://www.engie.com.br/wp-content/uploads/2026/02/260225-Release-de-Resultados-4T25.pdf
A35: Auren — the only listed generator publishing an explicit R$ curtailment table | B35: FY2025 gross R$529.5m, R$333.6m net of modulation gains | C35: https://ri.auren.com.br/
